Workbook

Sheet README
A1: Private AI Appliance - Pricing & Unit Economics Model
A2: Built 2026-09-25. Numbers are planning estimates from public research (see Sources column on each sheet), not quotes.
A4: HOW TO USE
A5: 1. Change inputs on 'Assumptions', 'Hardware BOM', 'Sales Plan' and 'Opex Plan'. Everything else recalculates.
A6: 2. Switch scenarios with Assumptions!B4 (1 = Conservative, 2 = Base, 3 = Upside).
A7: 3. Set Assumptions!B5 to 0 if clients buy hardware directly from the OEM (you then earn no hardware margin but carry no inventory risk).
A8: 4. Read results on 'Dashboard' (3-year view) and 'Unit Economics' (per-client view).
A10: COLOR LEGEND
A11: Blue text = hardcoded input you can change
A12: Black text = formula
A13: Green text = pulled from another sheet
A14: Yellow fill = key lever worth testing
... A23: - Hardware refreshes (typically every 3-5 years) are not modeled; they are upside.

Sheet Dashboard
A1: Dashboard: 3-year view
A2: =CHOOSE(Assumptions!$B$4,"Scenario: Conservative","Scenario: Base","Scenario: Upside")&IF(Assumptions!$B$5=1," | Hardware resold by you"," | Client buys hardware direct") -> Scenario: Base | Hardware resold by you
A4: Metric | B4: Year 1 | C4: Year 2 | D4: Year 3 | E4: Notes
A5: New clients signed | B5: =SUMIF(Projection!$B$3:$AK$3,1,Projection!$B$7:$AK$7)+SUMIF(Projection!$B$3:$AK$3,1,Projection!$B$8:$AK$8)+SUMIF(Projection!$B$3:$AK$3,1,Projection!$B$9:$AK$9) -> 5 | C5: =SUMIF(Projection!$B$3:$AK$3,2,Projection!$B$7:$AK$7)+SUMIF(Projection!$B$3:$AK$3,2,Projection!$B$8:$AK$8)+SUMIF(Projection!$B$3:$AK$3,2,Projection!$B$9:$AK$9) -> 16 | D5: =SUMIF(Projection!$B$3:$AK$3,3,Projection!$B$7:$AK$7)+SUMIF(Projection!$B$3:$AK$3,3,Projection!$B$8:$AK$8)+SUMIF(Projection!$B$3:$AK$3,3,Projection!$B$9:$AK$9) -> 30 | E5: Fractional = expected value
A6: Active clients at year end | B6: =INDEX(Projection!$B$15:$AK$15,1,12*1) -> 4.8540106 | C6: =INDEX(Projection!$B$15:$AK$15,1,12*2) -> 19.670875 | D6: =INDEX(Projection!$B$15:$AK$15,1,12*3) -> 46.403713
A7: Financials ($)
A8: Hardware revenue | B8: =SUMIF(Projection!$B$3:$AK$3,1,Projection!$B$18:$AK$18) -> 70325.95 | C8: =SUMIF(Projection!$B$3:$AK$3,2,Projection!$B$18:$AK$18) -> 297031.2 | D8: =SUMIF(Projection!$B$3:$AK$3,3,Projection!$B$18:$AK$18) -> 641790.85 | E8: Pass-through; thin margin
A9: Setup & onboarding revenue | B9: =SUMIF(Projection!$B$3:$AK$3,1,Projection!$B$19:$AK$19) -> 37500 | C9: =SUMIF(Projection!$B$3:$AK$3,2,Projection!$B$19:$AK$19) -> 145000 | D9: =SUMIF(Projection!$B$3:$AK$3,3,Projection!$B$19:$AK$19) -> 301500
A10: Subscription revenue | B10: =SUMIF(Projection!$B$3:$AK$3,1,Projection!$B$20:$AK$20) -> 34705.334 | C10: =SUMIF(Projection!$B$3:$AK$3,2,Projection!$B$20:$AK$20) -> 414690.3 | D10: =SUMIF(Projection!$B$3:$AK$3,3,Projection!$B$20:$AK$20) -> 1245645 | E10: The part that compounds
A11: Total revenue | B11: =SUM(B8:B10) -> 142531.28 | C11: =SUM(C8:C10) -> 856721.5 | D11: =SUM(D8:D10) -> 2188935.8
A12: Gross profit | B12: =SUMIF(Projection!$B$3:$AK$3,1,Projection!$B$28:$AK$28) -> 57953.591 | C12: =SUMIF(Projection!$B$3:$AK$3,2,Projection!$B$28:$AK$28) -> 474300.24 | D12: =SUMIF(Projection!$B$3:$AK$3,3,Projection!$B$28:$AK$28) -> 1315595.7
A13: Gross margin % | B13: =IF(B11=0,0,B12/B11) -> 0.4066026 | C13: =IF(C11=0,0,C12/C11) -> 0.55362243 | D13: =IF(D11=0,0,D12/D11) -> 0.60102068
A14: Operating expenses | B14: =SUMIF(Projection!$B$3:$AK$3,1,Projection!$B$40:$AK$40) -> 166540 | C14: =SUMIF(Projection!$B$3:$AK$3,2,Projection!$B$40:$AK$40) -> 613690 | D14: =SUMIF(Projection!$B$3:$AK$3,3,Projection!$B$40:$AK$40) -> 966130
A15: EBITDA | B15: =B12-B14 -> -108586.41 | C15: =C12-C14 -> -139389.76 | D15: =D12-D14 -> 349465.71
A16: Capital purchases | B16: =SUMIF(Projection!$B$3:$AK$3,1,Projection!$B$43:$AK$43) -> 28000 | C16: =SUMIF(Projection!$B$3:$AK$3,2,Projection!$B$43:$AK$43) -> 8000 | D16: =SUMIF(Projection!$B$3:$AK$3,3,Projection!$B$43:$AK$43) -> 0
A17: Cash balance at year end | B17: =INDEX(Projection!$B$45:$AK$45,1,12*1) -> -136586.41 | C17: =INDEX(Projection!$B$45:$AK$45,1,12*2) -> -283976.17 | D17: =INDEX(Projection!$B$45:$AK$45,1,12*3) -> 65489.534 | E17: Negative = funding required
A18: ARR at year end (list price) | B18: =INDEX(Projection!$B$47:$AK$47,1,12*1) -> 146076.13 | C18: =INDEX(Projection!$B$47:$AK$47,1,12*2) -> 689324.26 | D18: =INDEX(Projection!$B$47:$AK$47,1,12*3) -> 1780192.9 | E18: Annual recurring revenue run-rate
A19: Hires on payroll at year end (excl. founders) | B19: =Projection!$M$49+Projection!$M$50+Projection!$M$51+Projection!$M$52 -> 0 | C19: =Projection!$Y$49+Projection!$Y$50+Projection!$Y$51+Projection!$Y$52 -> 2 | D19: =Projection!$AK$49+Projection!$AK$50+Projection!$AK$51+Projection!$AK$52 -> 4 | E19: Hires start automatically when active clients reach the thresholds on 'Opex Plan'
A20: Key results
A21: Month EBITDA turns positive and stays positive | B21: =IF(MIN(Projection!$B$48:$AK$48)=999,"Not within 36 months",MIN(Projection!$B$48:$AK$48)) -> 23
A22: Lowest cash balance over 36 months ($) | B22: =MIN(Projection!$B$45:$AK$45) -> -286825.26
A23: Outside funding needed to stay above $0 ($) | B23: =MAX(0,-B22) -> 286825.26 | E23: Starting cash is on Assumptions!B6. Add a buffer of 3-6 months of opex on top.
A24: Clients active at month 36 | B24: =Projection!$AK$15 -> 46.403713
A26: Hiring plan
A27: Role | B27: Starts in month | C27: Threshold (clients)
A28: Field / solutions engineer | B28: =IFERROR(MATCH(1,Projection!$B$49:$AK$49,0),"Not within 36 months") -> 14 | C28: ='Opex Plan'!$C$13 -> 5
A29: Sales / partner manager (base; commission sits in CAC) | B29: =IFERROR(MATCH(1,Projection!$B$50:$AK$50,0),"Not within 36 months") -> 17 | C29: ='Opex Plan'!$C$14 -> 8
A30: Second engineer | B30: =IFERROR(MATCH(1,Projection!$B$51:$AK$51,0),"Not within 36 months") -> 28 | C30: ='Opex Plan'!$C$15 -> 25
A31: Customer success / support | B31: =IFERROR(MATCH(1,Projection!$B$52:$AK$52,0),"Not within 36 months") -> 35 | C31: ='Opex Plan'!$C$16 -> 40

Sheet Unit Economics
A1: Unit Economics: one client, by tier
A2: Reads from 'Assumptions'. List prices, before any design-partner discount.
A4: Per client | B4: Practice | C4: Firm | D4: Enterprise | E4: How it's calculated
A5: Hardware revenue (one-time) | B5: =Assumptions!B20*Assumptions!$B$5 -> 6323.85 | C5: =Assumptions!C20*Assumptions!$B$5 -> 25677.2 | D5: =Assumptions!D20*Assumptions!$B$5 -> 66700 | E5: Hardware price to client x resell toggle
A6: Setup & onboarding fee (one-time) | B6: =Assumptions!B11 -> 4500 | C6: =Assumptions!C11 -> 12000 | D6: =Assumptions!D11 -> 25000
A7: One-time revenue | B7: =B5+B6 -> 10823.85 | C7: =C5+C6 -> 37677.2 | D7: =D5+D6 -> 91700
A8: Hardware cost | B8: =Assumptions!B14*Assumptions!$B$5 -> 5499 | C8: =Assumptions!C14*Assumptions!$B$5 -> 22328 | D8: =Assumptions!D14*Assumptions!$B$5 -> 58000
A9: Install labor, travel & burn-in | B9: =Assumptions!B15*Assumptions!$B$23+Assumptions!B16 -> 2200 | C9: =Assumptions!C15*Assumptions!$B$23+Assumptions!C16 -> 4500 | D9: =Assumptions!D15*Assumptions!$B$23+Assumptions!D16 -> 11500 | E9: Hours x loaded rate + travel/shipping
A10: One-time gross profit | B10: =B7-B8-B9 -> 3124.85 | C10: =C7-C8-C9 -> 10849.2 | D10: =D7-D8-D9 -> 22200
A11: One-time gross margin | B11: =IF(B7=0,0,B10/B7) -> 0.28870042 | C11: =IF(C7=0,0,C10/C7) -> 0.28795133 | D11: =IF(D7=0,0,D10/D7) -> 0.24209378
A12: Recurring (monthly)
A13: Subscription ($/month) | B13: =Assumptions!B12 -> 1500 | C13: =Assumptions!C12 -> 4000 | D13: =Assumptions!D12 -> 8500
A14: Support labor & recurring cost ($/month) | B14: =Assumptions!B17*Assumptions!$B$23+Assumptions!B18 -> 275 | C14: =Assumptions!C17*Assumptions!$B$23+Assumptions!C18 -> 550 | D14: =Assumptions!D17*Assumptions!$B$23+Assumptions!D18 -> 1330 | E14: Support hours x loaded rate + other recurring
A15: Subscription gross profit ($/month) | B15: =B13-B14 -> 1225 | C15: =C13-C14 -> 3450 | D15: =D13-D14 -> 7170
A16: Subscription gross margin | B16: =IF(B13=0,0,B15/B13) -> 0.81666667 | C16: =IF(C13=0,0,C15/C13) -> 0.8625 | D16: =IF(D13=0,0,D15/D13) -> 0.84352941
A17: Effective price per user per month | B17: =IF(Assumptions!B10=0,0,B13/Assumptions!B10) -> 125 | C17: =IF(Assumptions!C10=0,0,C13/Assumptions!C10) -> 100 | D17: =IF(Assumptions!D10=0,0,D13/Assumptions!D10) -> 56.666667 | E17: Subscription / midpoint users: compare with per-seat cloud tools on 'Benchmarks'
A18: First year and lifetime
A19: Year-1 revenue per client | B19: =B7+12*B13 -> 28823.85 | C19: =C7+12*C13 -> 85677.2 | D19: =D7+12*D13 -> 193700 | E19: One-time + 12 months of subscription
A20: Year-1 gross profit per client | B20: =B10+12*B15 -> 17824.85 | C20: =C10+12*C15 -> 52249.2 | D20: =D10+12*D15 -> 108240
A21: Year-1 blended gross margin | B21: =IF(B19=0,0,B20/B19) -> 0.61840629 | C21: =IF(C19=0,0,C20/C19) -> 0.60983786 | D21: =IF(D19=0,0,D20/D19) -> 0.55880227 | E21: Low because hardware is a thin-margin pass-through
A22: Annual recurring revenue (Year 2 onward) | B22: =12*B13 -> 18000 | C22: =12*C13 -> 48000 | D22: =12*D13 -> 102000
A23: Annual recurring gross profit (Year 2 onward) | B23: =12*B15 -> 14700 | C23: =12*C15 -> 41400 | D23: =12*D15 -> 86040
A24: Acquisition payback
A25: Expected customer lifetime (years) | B25: =MIN(Assumptions!$B$30,IF(Assumptions!$B$24=0,Assumptions!$B$30,1/Assumptions!$B$24)) -> 5 | C25: =MIN(Assumptions!$B$30,IF(Assumptions!$B$24=0,Assumptions!$B$30,1/Assumptions!$B$24)) -> 5 | D25: =MIN(Assumptions!$B$30,IF(Assumptions!$B$24=0,Assumptions!$B$30,1/Assumptions!$B$24)) -> 5 | E25: 1 / annual churn, capped at the max lifetime
A26: Lifetime gross profit (LTV) | B26: =B10+B23*B25 -> 76624.85 | C26: =C10+C23*C25 -> 217849.2 | D26: =D10+D23*D25 -> 452400 | E26: One-time GP + recurring GP x lifetime (undiscounted)
A27: Customer acquisition cost (CAC) | B27: =Assumptions!B19 -> 6000 | C27: =Assumptions!C19 -> 12000 | D27: =Assumptions!D19 -> 25000
A28: LTV / CAC | B28: =IF(B27=0,0,B26/B27) -> 12.770808 | C28: =IF(C27=0,0,C26/C27) -> 18.1541 | D28: =IF(D27=0,0,D26/D27) -> 18.096 | E28: Above 3x is healthy for B2B
A29: Months of subscription profit to repay CAC | B29: =IF(B15<=0,0,MAX(0,B27-B10)/B15) -> 2.3470612 | C29: =IF(C15<=0,0,MAX(0,C27-C10)/C15) -> 0.33356522 | D29: =IF(D15<=0,0,MAX(0,D27-D10)/D15) -> 0.39051604 | E29: After one-time gross profit is applied; under 12 is strong
A30: Capacity
A31: Delivery hours per client in Year 1 | B31: =Assumptions!B15+12*Assumptions!B17 -> 50 | C31: =Assumptions!C15+12*Assumptions!C17 -> 100 | D31: =Assumptions!D15+12*Assumptions!D17 -> 244 | E31: Capacity planning
A32: Clients one support engineer can carry | B32: =IF(Assumptions!B17=0,0,Assumptions!$B$29/(12*Assumptions!B17)) -> 46.666667 | C32: =IF(Assumptions!C17=0,0,Assumptions!$B$29/(12*Assumptions!C17)) -> 23.333333 | D32: =IF(Assumptions!D17=0,0,Assumptions!$B$29/(12*Assumptions!D17)) -> 9.7222222 | E32: Engineer hours per year / support hours per client per year

Sheet Assumptions
A1: Assumptions
A2: Blue = input. Black = formula. Green = from another sheet. Yellow fill = key lever.
A4: Scenario (1 = Conservative, 2 = Base, 3 = Upside) | B4: 2
A5: Resell hardware? (1 = we resell it, 0 = client buys direct from OEM) | B5: 1
A6: Starting cash ($) | B6: 0
A8: Per-client assumptions | B8: Practice | C8: Firm | D8: Enterprise | E8: Notes / source
A9: Team size served (users) | B9: 5-20 | C9: 20-75 | D9: 75-300 | E9: Staff the box is sized for (see Hardware BOM capacity notes).
A10: Users for per-seat comparison (midpoint) | B10: 12 | C10: 40 | D10: 150 | E10: Used only to compare our flat price with per-seat cloud tools.
A11: Setup & onboarding fee ($, one-time) | B11: 4500 | C11: 12000 | D11: 25000 | E11: Covers burn-in, imaging, install, AD integration, workflow setup, training. Market: managed private-AI builds run $20k-90k in year one for medical practices (valuestreamai.com).
A12: Subscription ($/month) | B12: 1500 | C12: 4000 | D12: 8500 | E12: Flat monthly, no per-seat fees within the tier. ~$57-125 per user vs $199-500/seat for cloud legal AI (Clio Work, CoCounsel, Lexis) and $149-599/user for managed private AI (openclawinstall.ai). Appliance vendors earn most profit here (Datto subscriptions 84% gross margin).
A13: Hardware markup over cost (%) | B13: 0.15 | C13: 0.15 | D13: 0.15 | E13: Cost-plus pass-through. Benchmarks: channel hardware markup 20-28% and shrinking; CDW 21.7% gross margin FY2025; Datto sold appliances below cost to win subscriptions. Keep it thin: buyers can price-check a DGX Spark.
A14: Hardware cost to us ($) | B14: ='Hardware BOM'!$D$10 -> 5499 | C14: ='Hardware BOM'!$D$20 -> 22328 | D14: ='Hardware BOM'!$D$30 -> 58000 | E14: From 'Hardware BOM' totals.
A15: Install & onboarding labor (hours) | B15: 20 | C15: 40 | D15: 100 | E15: Your labor per install (burn-in, imaging, on-site, config, training).
A16: Travel, shipping & burn-in per install ($) | B16: 400 | C16: 900 | D16: 2500 | E16: Travel, insured shipping, burn-in consumables.
A17: Support & maintenance hours per client per month | B17: 2.5 | C17: 5 | D17: 12 | E17: Monthly engineer time: check-ins, user questions, quarterly updates (amortized), troubleshooting.
A18: Other recurring cost per client ($/month) | B18: 50 | C18: 100 | D18: 250 | E18: Update media, spare-parts reserve, monitoring and tooling per client.
A19: Sales & marketing cost to win one client (CAC, $) | B19: 6000 | C19: 12000 | D19: 25000 | E19: Founder time, travel, demo and pilot costs per closed deal. Cold email to legal/healthcare/finance gets ~0.6% replies (Belkins 2025), so most early deals come from warm intros, MSPs and CLE. Early-stage estimate; track actuals.
A20: Hardware price to client ($) | B20: =B14*(1+B13) -> 6323.85 | C20: =C14*(1+C13) -> 25677.2 | D20: =D14*(1+D13) -> 66700 | E20: Hardware cost x (1 + markup).
A22: Company-wide assumptions | B22: Value | E22: Notes / source
A23: Loaded delivery labor cost ($/hour) | B23: 90 | E23: ~$105k engineer salary + 20% burden over ~1,400 productive hours.
A24: Annual logo churn (%) | B24: 0.1 | E24: SMB SaaS typically loses 10-20% of customers per year; owned on-prem hardware should reduce churn. Assumption.
A25: Monthly churn (derived) | B25: =1-(1-B24)^(1/12) -> 0.008741611 | E25: Converts annual churn to a monthly rate.
A26: Year-1 design-partner discount on subscriptions (%) | B26: 0.3 | E26: Blended: design partners get ~50% off year one; later year-one clients pay list.
A27: Payroll taxes & benefits (% of salary) | B27: 0.2 | E27: Employer taxes + benefits. Assumption.
A28: Opex contingency (% of opex) | B28: 0.1 | E28: Buffer for costs not listed.
A29: Support hours one engineer can deliver per year | B29: 1400 | E29: Productive hours per engineer per year available for client support.
A30: Maximum customer lifetime used for LTV (years) | B30: 5 | E30: Caps LTV so low churn doesn't imply an unrealistic lifetime.

Sheet Sales Plan
A1: Sales Plan: new clients signed per quarter
A2: New signed clients per quarter. Q1 = Oct-Dec 2026 (product build, no installs).
A4: Scenario | B4: Tier | C4: Q1 | D4: Q2 | E4: Q3 | F4: Q4 | G4: Q5 | H4: Q6 | I4: Q7 | J4: Q8 | K4: Q9 | L4: Q10 | M4: Q11 | N4: Q12 | O4: 3-yr total
A5: Conservative | B5: Practice | C5: 0 | D5: 0 | E5: 1 | F5: 1 | G5: 1 | H5: 1 | I5: 1 | J5: 2 | K5: 2 | L5: 2 | M5: 2 | N5: 2 | O5: =SUM(C5:N5) -> 15 | P5: Base: Q1 (Oct-Dec 2026) builds the demo-ready product. Q2-Q4 are 5 design partners and referrals, founder-led in one metro. Year 2 (16 clients) adds a sales/partner hire and 2-3 MSP partners. Year 3 (30 clients) adds a second metro or vertical. Conservative is ~55% of Base; Upside assumes MSP partners each bring several clients. Reality check: at ~0.6% cold-email reply rates (Belkins 2025), cold outreach alone would not produce these numbers.
A6: Conservative | B6: Firm | C6: 0 | D6: 0 | E6: 0 | F6: 1 | G6: 1 | H6: 1 | I6: 1 | J6: 1 | K6: 1 | L6: 2 | M6: 2 | N6: 2 | O6: =SUM(C6:N6) -> 12
A7: Conservative | B7: Enterprise | C7: 0 | D7: 0 | E7: 0 | F7: 0 | G7: 0 | H7: 0 | I7: 0 | J7: 0 | K7: 0 | L7: 1 | M7: 0 | N7: 1 | O7: =SUM(C7:N7) -> 2
A8: Base | B8: Practice | C8: 0 | D8: 1 | E8: 1 | F8: 1 | G8: 2 | H8: 2 | I8: 2 | J8: 2 | K8: 3 | L8: 3 | M8: 3 | N8: 4 | O8: =SUM(C8:N8) -> 24
A9: Base | B9: Firm | C9: 0 | D9: 0 | E9: 1 | F9: 1 | G9: 1 | H9: 2 | I9: 2 | J9: 2 | K9: 3 | L9: 3 | M9: 4 | N9: 4 | O9: =SUM(C9:N9) -> 23
A10: Base | B10: Enterprise | C10: 0 | D10: 0 | E10: 0 | F10: 0 | G10: 0 | H10: 0 | I10: 1 | J10: 0 | K10: 1 | L10: 0 | M10: 1 | N10: 1 | O10: =SUM(C10:N10) -> 4
A11: Upside | B11: Practice | C11: 0 | D11: 1 | E11: 2 | F11: 2 | G11: 3 | H11: 3 | I11: 3 | J11: 4 | K11: 4 | L11: 5 | M11: 5 | N11: 5 | O11: =SUM(C11:N11) -> 37
A12: Upside | B12: Firm | C12: 0 | D12: 1 | E12: 1 | F12: 2 | G12: 2 | H12: 3 | I12: 3 | J12: 3 | K12: 4 | L12: 4 | M12: 5 | N12: 5 | O12: =SUM(C12:N12) -> 33
A13: Upside | B13: Enterprise | C13: 0 | D13: 0 | E13: 0 | F13: 1 | G13: 0 | H13: 1 | I13: 1 | J13: 1 | K13: 1 | L13: 1 | M13: 2 | N13: 2 | O13: =SUM(C13:N13) -> 10
A15: Selected scenario (driven by Assumptions!B4)
A16: Selected | B16: Practice | C16: =CHOOSE(Assumptions!$B$4,C5,C8,C11) -> 0 | D16: =CHOOSE(Assumptions!$B$4,D5,D8,D11) -> 1 | E16: =CHOOSE(Assumptions!$B$4,E5,E8,E11) -> 1 | F16: =CHOOSE(Assumptions!$B$4,F5,F8,F11) -> 1 | G16: =CHOOSE(Assumptions!$B$4,G5,G8,G11) -> 2 | H16: =CHOOSE(Assumptions!$B$4,H5,H8,H11) -> 2 | I16: =CHOOSE(Assumptions!$B$4,I5,I8,I11) -> 2 | J16: =CHOOSE(Assumptions!$B$4,J5,J8,J11) -> 2 | ... N16: =CHOOSE(Assumptions!$B$4,N5,N8,N11) -> 4 | O16: =SUM(C16:N16) -> 24
A17: Selected | B17: Firm | C17: =CHOOSE(Assumptions!$B$4,C6,C9,C12) -> 0 | D17: =CHOOSE(Assumptions!$B$4,D6,D9,D12) -> 0 | E17: =CHOOSE(Assumptions!$B$4,E6,E9,E12) -> 1 | F17: =CHOOSE(Assumptions!$B$4,F6,F9,F12) -> 1 | G17: =CHOOSE(Assumptions!$B$4,G6,G9,G12) -> 1 | H17: =CHOOSE(Assumptions!$B$4,H6,H9,H12) -> 2 | I17: =CHOOSE(Assumptions!$B$4,I6,I9,I12) -> 2 | J17: =CHOOSE(Assumptions!$B$4,J6,J9,J12) -> 2 | ... N17: =CHOOSE(Assumptions!$B$4,N6,N9,N12) -> 4 | O17: =SUM(C17:N17) -> 23
A18: Selected | B18: Enterprise | C18: =CHOOSE(Assumptions!$B$4,C7,C10,C13) -> 0 | D18: =CHOOSE(Assumptions!$B$4,D7,D10,D13) -> 0 | E18: =CHOOSE(Assumptions!$B$4,E7,E10,E13) -> 0 | F18: =CHOOSE(Assumptions!$B$4,F7,F10,F13) -> 0 | G18: =CHOOSE(Assumptions!$B$4,G7,G10,G13) -> 0 | H18: =CHOOSE(Assumptions!$B$4,H7,H10,H13) -> 0 | I18: =CHOOSE(Assumptions!$B$4,I7,I10,I13) -> 1 | J18: =CHOOSE(Assumptions!$B$4,J7,J10,J13) -> 0 | ... N18: =CHOOSE(Assumptions!$B$4,N7,N10,N13) -> 1 | O18: =SUM(C18:N18) -> 4

Sheet Opex Plan
A1: Operating Expenses Plan
A2: Annual amounts; the Projection spreads them evenly over each year's months.
A3: Annual operating costs ($) | B3: Year 1 | C3: Year 2 | D3: Year 3 | E3: Notes / source
A4: Founder pay (total, all founders) | B4: 72000 | C4: 192000 | D4: 264000 | E4: Assumes 2 founders at $3k/month each in Year 1, $8k in Year 2, $11k in Year 3. Set to $0 if living on savings.
A5: Software, data and website | B5: 10000 | C5: 20000 | D5: 30000 | E5: Prospecting tools $3.6k (lean) to $14.2k (moderate) per year: Sales Navigator $1,080-1,800/yr, Apollo $49-119/user/mo, Hunter $34/mo, Clay $167+/mo. Plus Google Workspace, GitHub, website hosting, CRM.
A6: Insurance (tech E&O + cyber + general liability) | B6: 4000 | C6: 8000 | D6: 14000 | E6: Year 1 ~$3,900 at Insureon averages (tech E&O $110/mo, cyber $179/mo, GL $37/mo). Later years move toward Vouch startup medians (E&O $3,700, cyber $2,900) and add D&O ($6,300).
A7: Legal, accounting and trademark | B7: 15000 | C7: 15000 | D7: 20000 | E7: Formation $500 (Stripe Atlas); MSA, pilot, BAA and reseller contracts $3k-15k; bookkeeping and tax $3k-6k; trademark clearance and filing. Estimates.
A8: Security audits (pen test, SOC 2) | B8: 9000 | C8: 37000 | D8: 45000 | E8: Year 1: appliance pen test ~$5k + HIPAA program ~$4k. Year 2: Vanta ~$14k + SOC 2 Type I ~$12k + pen test + HIPAA upkeep. Year 3: SOC 2 Type II ($15.5k-50k) instead of Type I. Sources: soc2auditors.org, brightdefense.com, medcurity.com (2026).
A9: Marketing, events and CLE | B9: 15000 | C9: 40000 | D9: 70000 | E9: Year 1: ABA TECHSHOW 10x10 booth $5,050 + furniture $1,855 (Mar 2027), CLE accreditation fees (CA $159/activity; IL $50/course + $0.75/attorney-hour), local association sponsorships, content. Later: AICPA ENGAGE booth $6,800, state association booths ~$1.5-2k, Legalweek.
A10: Sales travel | B10: 12000 | C10: 24000 | D10: 36000 | E10: Local metro demos in Year 1 plus one national show; regional in Years 2-3. Assumption.
A12: Hires (salaried) | B12: Annual salary ($) | C12: Hire when active clients reach | E12: Notes / source
A13: Field / solutions engineer | B13: 105000 | C13: 5 | E13: Installs start crowding out selling at ~5 clients. Salary is an assumption.
A14: Sales / partner manager (base; commission sits in CAC) | B14: 85000 | C14: 8 | E14: Owns MSP partnerships and outbound. Salary is an assumption.
A15: Second engineer | B15: 115000 | C15: 25 | E15: One engineer carries ~25-45 Practice/Firm clients (Unit Economics row 32). Assumption.
A16: Customer success / support | B16: 75000 | C16: 40 | E16: Assumption.
A18: Capital purchases | B18: Amount ($) | C18: Month (1-36) | E18: Notes / source
A19: Portable demo box (ASUS Ascent GX10 / DGX Spark) + UPS | B19: 5500 | C19: 1 | E19: ASUS GX10 $3,999 / DGX Spark $4,699 (Sept 2026).
A20: Pilot / loaner workstation (1x RTX PRO 6000) | B20: 22500 | C20: 5 | E20: Same as Firm tier BOM. Used for paid pilots, then as a lab box.
A21: Second demo box + spare parts pool | B21: 8000 | C21: 13 | E21: Assumption

Sheet Projection
A1: 36-Month Projection (monthly, USD)
A2: Month | B2: 1 | C2: 2 | D2: 3 | E2: 4 | F2: 5 | G2: 6 | H2: 7 | I2: 8 | J2: 9 | K2: 10 | L2: 11 | M2: 12 | N2: 13 | O2: 14 | P2: 15 | Q2: 16 | R2: 17 | S2: 18 | T2: 19 | U2: 20 | V2: 21 | W2: 22 | X2: 23 | Y2: 24 | Z2: 25 | AA2: 26 | AB2: 27 | AC2: 28 | AD2: 29 | AE2: 30 | AF2: 31 | AG2: 32 | AH2: 33 | AI2: 34 | AJ2: 35 | AK2: 36
A3: Year | B3: =ROUNDUP(B2/12,0) -> 1 | C3: =ROUNDUP(C2/12,0) -> 1 | D3: =ROUNDUP(D2/12,0) -> 1 | E3: =ROUNDUP(E2/12,0) -> 1 | F3: =ROUNDUP(F2/12,0) -> 1 | G3: =ROUNDUP(G2/12,0) -> 1 | H3: =ROUNDUP(H2/12,0) -> 1 | I3: =ROUNDUP(I2/12,0) -> 1 | ... AK3: =ROUNDUP(AK2/12,0) -> 3
A4: Quarter | B4: =ROUNDUP(B2/3,0) -> 1 | C4: =ROUNDUP(C2/3,0) -> 1 | D4: =ROUNDUP(D2/3,0) -> 1 | E4: =ROUNDUP(E2/3,0) -> 2 | F4: =ROUNDUP(F2/3,0) -> 2 | G4: =ROUNDUP(G2/3,0) -> 2 | H4: =ROUNDUP(H2/3,0) -> 3 | I4: =ROUNDUP(I2/3,0) -> 3 | ... AK4: =ROUNDUP(AK2/3,0) -> 12
A6: New clients signed
A7: Practice | B7: =INDEX('Sales Plan'!$C$16:$N$16,1,B$4)/3 -> 0 | C7: =INDEX('Sales Plan'!$C$16:$N$16,1,C$4)/3 -> 0 | D7: =INDEX('Sales Plan'!$C$16:$N$16,1,D$4)/3 -> 0 | E7: =INDEX('Sales Plan'!$C$16:$N$16,1,E$4)/3 -> 0.33333333 | F7: =INDEX('Sales Plan'!$C$16:$N$16,1,F$4)/3 -> 0.33333333 | G7: =INDEX('Sales Plan'!$C$16:$N$16,1,G$4)/3 -> 0.33333333 | H7: =INDEX('Sales Plan'!$C$16:$N$16,1,H$4)/3 -> 0.33333333 | I7: =INDEX('Sales Plan'!$C$16:$N$16,1,I$4)/3 -> 0.33333333 | ... AK7: =INDEX('Sales Plan'!$C$16:$N$16,1,AK$4)/3 -> 1.3333333
A8: Firm | B8: =INDEX('Sales Plan'!$C$17:$N$17,1,B$4)/3 -> 0 | C8: =INDEX('Sales Plan'!$C$17:$N$17,1,C$4)/3 -> 0 | D8: =INDEX('Sales Plan'!$C$17:$N$17,1,D$4)/3 -> 0 | E8: =INDEX('Sales Plan'!$C$17:$N$17,1,E$4)/3 -> 0 | F8: =INDEX('Sales Plan'!$C$17:$N$17,1,F$4)/3 -> 0 | G8: =INDEX('Sales Plan'!$C$17:$N$17,1,G$4)/3 -> 0 | H8: =INDEX('Sales Plan'!$C$17:$N$17,1,H$4)/3 -> 0.33333333 | I8: =INDEX('Sales Plan'!$C$17:$N$17,1,I$4)/3 -> 0.33333333 | ... AK8: =INDEX('Sales Plan'!$C$17:$N$17,1,AK$4)/3 -> 1.3333333
A9: Enterprise | B9: =INDEX('Sales Plan'!$C$18:$N$18,1,B$4)/3 -> 0 | C9: =INDEX('Sales Plan'!$C$18:$N$18,1,C$4)/3 -> 0 | D9: =INDEX('Sales Plan'!$C$18:$N$18,1,D$4)/3 -> 0 | E9: =INDEX('Sales Plan'!$C$18:$N$18,1,E$4)/3 -> 0 | F9: =INDEX('Sales Plan'!$C$18:$N$18,1,F$4)/3 -> 0 | G9: =INDEX('Sales Plan'!$C$18:$N$18,1,G$4)/3 -> 0 | H9: =INDEX('Sales Plan'!$C$18:$N$18,1,H$4)/3 -> 0 | I9: =INDEX('Sales Plan'!$C$18:$N$18,1,I$4)/3 -> 0 | ... AK9: =INDEX('Sales Plan'!$C$18:$N$18,1,AK$4)/3 -> 0.33333333
A11: Active clients (end of month)
A12: Practice | B12: =B7 -> 0 | C12: =B12*(1-Assumptions!$B$25)+C7 -> 0 | D12: =C12*(1-Assumptions!$B$25)+D7 -> 0 | E12: =D12*(1-Assumptions!$B$25)+E7 -> 0.33333333 | F12: =E12*(1-Assumptions!$B$25)+F7 -> 0.6637528 | G12: =F12*(1-Assumptions!$B$25)+G7 -> 0.99128386 | H12: =G12*(1-Assumptions!$B$25)+H7 -> 1.3159518 | I12: =H12*(1-Assumptions!$B$25)+I7 -> 1.6377816 | J12: =I12*(1-Assumptions!$B$25)+J7 -> 1.9567981 | ... AK12: =AJ12*(1-Assumptions!$B$25)+AK7 -> 21.641288
A13: Firm | B13: =B8 -> 0 | C13: =B13*(1-Assumptions!$B$25)+C8 -> 0 | D13: =C13*(1-Assumptions!$B$25)+D8 -> 0 | E13: =D13*(1-Assumptions!$B$25)+E8 -> 0 | F13: =E13*(1-Assumptions!$B$25)+F8 -> 0 | G13: =F13*(1-Assumptions!$B$25)+G8 -> 0 | H13: =G13*(1-Assumptions!$B$25)+H8 -> 0.33333333 | I13: =H13*(1-Assumptions!$B$25)+I8 -> 0.6637528 | J13: =I13*(1-Assumptions!$B$25)+J8 -> 0.99128386 | ... AK13: =AJ13*(1-Assumptions!$B$25)+AK8 -> 21.020697
A14: Enterprise | B14: =B9 -> 0 | C14: =B14*(1-Assumptions!$B$25)+C9 -> 0 | D14: =C14*(1-Assumptions!$B$25)+D9 -> 0 | E14: =D14*(1-Assumptions!$B$25)+E9 -> 0 | F14: =E14*(1-Assumptions!$B$25)+F9 -> 0 | G14: =F14*(1-Assumptions!$B$25)+G9 -> 0 | H14: =G14*(1-Assumptions!$B$25)+H9 -> 0 | I14: =H14*(1-Assumptions!$B$25)+I9 -> 0 | J14: =I14*(1-Assumptions!$B$25)+J9 -> 0 | ... AK14: =AJ14*(1-Assumptions!$B$25)+AK9 -> 3.741728
A15: Total active clients | B15: =SUM(B12:B14) -> 0 | C15: =SUM(C12:C14) -> 0 | D15: =SUM(D12:D14) -> 0 | E15: =SUM(E12:E14) -> 0.33333333 | F15: =SUM(F12:F14) -> 0.6637528 | G15: =SUM(G12:G14) -> 0.99128386 | H15: =SUM(H12:H14) -> 1.6492851 | I15: =SUM(I12:I14) -> 2.3015344 | ... AK15: =SUM(AK12:AK14) -> 46.403713
A17: Revenue
A18: Hardware resale | B18: =(B7*Assumptions!$B$20+B8*Assumptions!$C$20+B9*Assumptions!$D$20)*Assumptions!$B$5 -> 0 | C18: =(C7*Assumptions!$B$20+C8*Assumptions!$C$20+C9*Assumptions!$D$20)*Assumptions!$B$5 -> 0 | D18: =(D7*Assumptions!$B$20+D8*Assumptions!$C$20+D9*Assumptions!$D$20)*Assumptions!$B$5 -> 0 | E18: =(E7*Assumptions!$B$20+E8*Assumptions!$C$20+E9*Assumptions!$D$20)*Assumptions!$B$5 -> 2107.95 | F18: =(F7*Assumptions!$B$20+F8*Assumptions!$C$20+F9*Assumptions!$D$20)*Assumptions!$B$5 -> 2107.95 | G18: =(G7*Assumptions!$B$20+G8*Assumptions!$C$20+G9*Assumptions!$D$20)*Assumptions!$B$5 -> 2107.95 | H18: =(H7*Assumptions!$B$20+H8*Assumptions!$C$20+H9*Assumptions!$D$20)*Assumptions!$B$5 -> 10667.017 | I18: =(I7*Assumptions!$B$20+I8*Assumptions!$C$20+I9*Assumptions!$D$20)*Assumptions!$B$5 -> 10667.017 | ... AK18: =(AK7*Assumptions!$B$20+AK8*Assumptions!$C$20+AK9*Assumptions!$D$20)*Assumptions!$B$5 -> 64901.4
A19: Setup & onboarding fees | B19: =B7*Assumptions!$B$11+B8*Assumptions!$C$11+B9*Assumptions!$D$11 -> 0 | C19: =C7*Assumptions!$B$11+C8*Assumptions!$C$11+C9*Assumptions!$D$11 -> 0 | D19: =D7*Assumptions!$B$11+D8*Assumptions!$C$11+D9*Assumptions!$D$11 -> 0 | E19: =E7*Assumptions!$B$11+E8*Assumptions!$C$11+E9*Assumptions!$D$11 -> 1500 | F19: =F7*Assumptions!$B$11+F8*Assumptions!$C$11+F9*Assumptions!$D$11 -> 1500 | G19: =G7*Assumptions!$B$11+G8*Assumptions!$C$11+G9*Assumptions!$D$11 -> 1500 | H19: =H7*Assumptions!$B$11+H8*Assumptions!$C$11+H9*Assumptions!$D$11 -> 5500 | I19: =I7*Assumptions!$B$11+I8*Assumptions!$C$11+I9*Assumptions!$D$11 -> 5500 | ... AK19: =AK7*Assumptions!$B$11+AK8*Assumptions!$C$11+AK9*Assumptions!$D$11 -> 30333.333
A20: Subscriptions | B20: =(B12*Assumptions!$B$12+B13*Assumptions!$C$12+B14*Assumptions!$D$12)*(1-IF(B$3=1,Assumptions!$B$26,0)) -> 0 | C20: =(C12*Assumptions!$B$12+C13*Assumptions!$C$12+C14*Assumptions!$D$12)*(1-IF(C$3=1,Assumptions!$B$26,0)) -> 0 | D20: =(D12*Assumptions!$B$12+D13*Assumptions!$C$12+D14*Assumptions!$D$12)*(1-IF(D$3=1,Assumptions!$B$26,0)) -> 0 | E20: =(E12*Assumptions!$B$12+E13*Assumptions!$C$12+E14*Assumptions!$D$12)*(1-IF(E$3=1,Assumptions!$B$26,0)) -> 350 | F20: =(F12*Assumptions!$B$12+F13*Assumptions!$C$12+F14*Assumptions!$D$12)*(1-IF(F$3=1,Assumptions!$B$26,0)) -> 696.94044 | G20: =(G12*Assumptions!$B$12+G13*Assumptions!$C$12+G14*Assumptions!$D$12)*(1-IF(G$3=1,Assumptions!$B$26,0)) -> 1040.8481 | H20: =(H12*Assumptions!$B$12+H13*Assumptions!$C$12+H14*Assumptions!$D$12)*(1-IF(H$3=1,Assumptions!$B$26,0)) -> 2315.0827 | I20: =(I12*Assumptions!$B$12+I13*Assumptions!$C$12+I14*Assumptions!$D$12)*(1-IF(I$3=1,Assumptions!$B$26,0)) -> 3578.1785 | ... AK20: =(AK12*Assumptions!$B$12+AK13*Assumptions!$C$12+AK14*Assumptions!$D$12)*(1-IF(AK$3=1,Assumptions!$B$26,0)) -> 148349.41
A21: Total revenue | B21: =SUM(B18:B20) -> 0 | C21: =SUM(C18:C20) -> 0 | D21: =SUM(D18:D20) -> 0 | E21: =SUM(E18:E20) -> 3957.95 | F21: =SUM(F18:F20) -> 4304.8904 | G21: =SUM(G18:G20) -> 4648.7981 | H21: =SUM(H18:H20) -> 18482.099 | I21: =SUM(I18:I20) -> 19745.195 | ... AK21: =SUM(AK18:AK20) -> 243584.14
A23: Cost of revenue
A24: Hardware cost | B24: =(B7*Assumptions!$B$14+B8*Assumptions!$C$14+B9*Assumptions!$D$14)*Assumptions!$B$5 -> 0 | C24: =(C7*Assumptions!$B$14+C8*Assumptions!$C$14+C9*Assumptions!$D$14)*Assumptions!$B$5 -> 0 | D24: =(D7*Assumptions!$B$14+D8*Assumptions!$C$14+D9*Assumptions!$D$14)*Assumptions!$B$5 -> 0 | E24: =(E7*Assumptions!$B$14+E8*Assumptions!$C$14+E9*Assumptions!$D$14)*Assumptions!$B$5 -> 1833 | F24: =(F7*Assumptions!$B$14+F8*Assumptions!$C$14+F9*Assumptions!$D$14)*Assumptions!$B$5 -> 1833 | G24: =(G7*Assumptions!$B$14+G8*Assumptions!$C$14+G9*Assumptions!$D$14)*Assumptions!$B$5 -> 1833 | H24: =(H7*Assumptions!$B$14+H8*Assumptions!$C$14+H9*Assumptions!$D$14)*Assumptions!$B$5 -> 9275.6667 | I24: =(I7*Assumptions!$B$14+I8*Assumptions!$C$14+I9*Assumptions!$D$14)*Assumptions!$B$5 -> 9275.6667 | ... AK24: =(AK7*Assumptions!$B$14+AK8*Assumptions!$C$14+AK9*Assumptions!$D$14)*Assumptions!$B$5 -> 56436
A25: Install labor, travel & burn-in | B25: =B7*(Assumptions!$B$15*Assumptions!$B$23+Assumptions!$B$16)+B8*(Assumptions!$C$15*Assumptions!$B$23+Assumptions!$C$16)+B9*(Assumptions!$D$15*Assumptions!$B$23+Assumptions!$D$16) -> 0 | C25: =C7*(Assumptions!$B$15*Assumptions!$B$23+Assumptions!$B$16)+C8*(Assumptions!$C$15*Assumptions!$B$23+Assumptions!$C$16)+C9*(Assumptions!$D$15*Assumptions!$B$23+Assumptions!$D$16) -> 0 | D25: =D7*(Assumptions!$B$15*Assumptions!$B$23+Assumptions!$B$16)+D8*(Assumptions!$C$15*Assumptions!$B$23+Assumptions!$C$16)+D9*(Assumptions!$D$15*Assumptions!$B$23+Assumptions!$D$16) -> 0 | E25: =E7*(Assumptions!$B$15*Assumptions!$B$23+Assumptions!$B$16)+E8*(Assumptions!$C$15*Assumptions!$B$23+Assumptions!$C$16)+E9*(Assumptions!$D$15*Assumptions!$B$23+Assumptions!$D$16) -> 733.33333 | F25: =F7*(Assumptions!$B$15*Assumptions!$B$23+Assumptions!$B$16)+F8*(Assumptions!$C$15*Assumptions!$B$23+Assumptions!$C$16)+F9*(Assumptions!$D$15*Assumptions!$B$23+Assumptions!$D$16) -> 733.33333 | G25: =G7*(Assumptions!$B$15*Assumptions!$B$23+Assumptions!$B$16)+G8*(Assumptions!$C$15*Assumptions!$B$23+Assumptions!$C$16)+G9*(Assumptions!$D$15*Assumptions!$B$23+Assumptions!$D$16) -> 733.33333 | H25: =H7*(Assumptions!$B$15*Assumptions!$B$23+Assumptions!$B$16)+H8*(Assumptions!$C$15*Assumptions!$B$23+Assumptions!$C$16)+H9*(Assumptions!$D$15*Assumptions!$B$23+Assumptions!$D$16) -> 2233.3333 | I25: =I7*(Assumptions!$B$15*Assumptions!$B$23+Assumptions!$B$16)+I8*(Assumptions!$C$15*Assumptions!$B$23+Assumptions!$C$16)+I9*(Assumptions!$D$15*Assumptions!$B$23+Assumptions!$D$16) -> 2233.3333 | ... AK25: =AK7*(Assumptions!$B$15*Assumptions!$B$23+Assumptions!$B$16)+AK8*(Assumptions!$C$15*Assumptions!$B$23+Assumptions!$C$16)+AK9*(Assumptions!$D$15*Assumptions!$B$23+Assumptions!$D$16) -> 12766.667
A26: Support labor & recurring costs | B26: =B12*(Assumptions!$B$17*Assumptions!$B$23+Assumptions!$B$18)+B13*(Assumptions!$C$17*Assumptions!$B$23+Assumptions!$C$18)+B14*(Assumptions!$D$17*Assumptions!$B$23+Assumptions!$D$18) -> 0 | C26: =C12*(Assumptions!$B$17*Assumptions!$B$23+Assumptions!$B$18)+C13*(Assumptions!$C$17*Assumptions!$B$23+Assumptions!$C$18)+C14*(Assumptions!$D$17*Assumptions!$B$23+Assumptions!$D$18) -> 0 | D26: =D12*(Assumptions!$B$17*Assumptions!$B$23+Assumptions!$B$18)+D13*(Assumptions!$C$17*Assumptions!$B$23+Assumptions!$C$18)+D14*(Assumptions!$D$17*Assumptions!$B$23+Assumptions!$D$18) -> 0 | E26: =E12*(Assumptions!$B$17*Assumptions!$B$23+Assumptions!$B$18)+E13*(Assumptions!$C$17*Assumptions!$B$23+Assumptions!$C$18)+E14*(Assumptions!$D$17*Assumptions!$B$23+Assumptions!$D$18) -> 91.666667 | F26: =F12*(Assumptions!$B$17*Assumptions!$B$23+Assumptions!$B$18)+F13*(Assumptions!$C$17*Assumptions!$B$23+Assumptions!$C$18)+F14*(Assumptions!$D$17*Assumptions!$B$23+Assumptions!$D$18) -> 182.53202 | G26: =G12*(Assumptions!$B$17*Assumptions!$B$23+Assumptions!$B$18)+G13*(Assumptions!$C$17*Assumptions!$B$23+Assumptions!$C$18)+G14*(Assumptions!$D$17*Assumptions!$B$23+Assumptions!$D$18) -> 272.60306 | H26: =H12*(Assumptions!$B$17*Assumptions!$B$23+Assumptions!$B$18)+H13*(Assumptions!$C$17*Assumptions!$B$23+Assumptions!$C$18)+H14*(Assumptions!$D$17*Assumptions!$B$23+Assumptions!$D$18) -> 545.22007 | I26: =I12*(Assumptions!$B$17*Assumptions!$B$23+Assumptions!$B$18)+I13*(Assumptions!$C$17*Assumptions!$B$23+Assumptions!$C$18)+I14*(Assumptions!$D$17*Assumptions!$B$23+Assumptions!$D$18) -> 815.45397 | ... AK26: =AK12*(Assumptions!$B$17*Assumptions!$B$23+Assumptions!$B$18)+AK13*(Assumptions!$C$17*Assumptions!$B$23+Assumptions!$C$18)+AK14*(Assumptions!$D$17*Assumptions!$B$23+Assumptions!$D$18) -> 22489.236
A27: Total cost of revenue | B27: =SUM(B24:B26) -> 0 | C27: =SUM(C24:C26) -> 0 | D27: =SUM(D24:D26) -> 0 | E27: =SUM(E24:E26) -> 2658 | F27: =SUM(F24:F26) -> 2748.8654 | G27: =SUM(G24:G26) -> 2838.9364 | H27: =SUM(H24:H26) -> 12054.22 | I27: =SUM(I24:I26) -> 12324.454 | ... AK27: =SUM(AK24:AK26) -> 91691.902
A28: Gross profit | B28: =B21-B27 -> 0 | C28: =C21-C27 -> 0 | D28: =D21-D27 -> 0 | E28: =E21-E27 -> 1299.95 | F28: =F21-F27 -> 1556.0251 | G28: =G21-G27 -> 1809.8617 | H28: =H21-H27 -> 6427.8793 | I28: =I21-I27 -> 7420.7412 | ... AK28: =AK21-AK27 -> 151892.24
A29: Gross margin % | B29: =IF(B21=0,0,B28/B21) -> 0 | C29: =IF(C21=0,0,C28/C21) -> 0 | D29: =IF(D21=0,0,D28/D21) -> 0 | E29: =IF(E21=0,0,E28/E21) -> 0.32844023 | F29: =IF(F21=0,0,F28/F21) -> 0.36145521 | G29: =IF(G21=0,0,G28/G21) -> 0.38931819 | H29: =IF(H21=0,0,H28/H21) -> 0.34778946 | I29: =IF(I21=0,0,I28/I21) -> 0.37582516 | ... AK29: =IF(AK21=0,0,AK28/AK21) -> 0.62357195
A31: Operating expenses
A32: Payroll (founders + hires, incl. taxes & benefits) | B32: =(INDEX('Opex Plan'!$B$4:$D$4,1,B$3)/12+SUMPRODUCT(B49:B52,'Opex Plan'!$B$13:$B$16)/12)*(1+Assumptions!$B$27) -> 7200 | C32: =(INDEX('Opex Plan'!$B$4:$D$4,1,C$3)/12+SUMPRODUCT(C49:C52,'Opex Plan'!$B$13:$B$16)/12)*(1+Assumptions!$B$27) -> 7200 | D32: =(INDEX('Opex Plan'!$B$4:$D$4,1,D$3)/12+SUMPRODUCT(D49:D52,'Opex Plan'!$B$13:$B$16)/12)*(1+Assumptions!$B$27) -> 7200 | E32: =(INDEX('Opex Plan'!$B$4:$D$4,1,E$3)/12+SUMPRODUCT(E49:E52,'Opex Plan'!$B$13:$B$16)/12)*(1+Assumptions!$B$27) -> 7200 | F32: =(INDEX('Opex Plan'!$B$4:$D$4,1,F$3)/12+SUMPRODUCT(F49:F52,'Opex Plan'!$B$13:$B$16)/12)*(1+Assumptions!$B$27) -> 7200 | G32: =(INDEX('Opex Plan'!$B$4:$D$4,1,G$3)/12+SUMPRODUCT(G49:G52,'Opex Plan'!$B$13:$B$16)/12)*(1+Assumptions!$B$27) -> 7200 | H32: =(INDEX('Opex Plan'!$B$4:$D$4,1,H$3)/12+SUMPRODUCT(H49:H52,'Opex Plan'!$B$13:$B$16)/12)*(1+Assumptions!$B$27) -> 7200 | I32: =(INDEX('Opex Plan'!$B$4:$D$4,1,I$3)/12+SUMPRODUCT(I49:I52,'Opex Plan'!$B$13:$B$16)/12)*(1+Assumptions!$B$27) -> 7200 | ... AK32: =(INDEX('Opex Plan'!$B$4:$D$4,1,AK$3)/12+SUMPRODUCT(AK49:AK52,'Opex Plan'!$B$13:$B$16)/12)*(1+Assumptions!$B$27) -> 64400
A33: Software, data and website | B33: =INDEX('Opex Plan'!$B$5:$D$5,1,B$3)/12 -> 833.33333 | C33: =INDEX('Opex Plan'!$B$5:$D$5,1,C$3)/12 -> 833.33333 | D33: =INDEX('Opex Plan'!$B$5:$D$5,1,D$3)/12 -> 833.33333 | E33: =INDEX('Opex Plan'!$B$5:$D$5,1,E$3)/12 -> 833.33333 | F33: =INDEX('Opex Plan'!$B$5:$D$5,1,F$3)/12 -> 833.33333 | G33: =INDEX('Opex Plan'!$B$5:$D$5,1,G$3)/12 -> 833.33333 | H33: =INDEX('Opex Plan'!$B$5:$D$5,1,H$3)/12 -> 833.33333 | I33: =INDEX('Opex Plan'!$B$5:$D$5,1,I$3)/12 -> 833.33333 | ... AK33: =INDEX('Opex Plan'!$B$5:$D$5,1,AK$3)/12 -> 2500
A34: Insurance (tech E&O + cyber + general liability) | B34: =INDEX('Opex Plan'!$B$6:$D$6,1,B$3)/12 -> 333.33333 | C34: =INDEX('Opex Plan'!$B$6:$D$6,1,C$3)/12 -> 333.33333 | D34: =INDEX('Opex Plan'!$B$6:$D$6,1,D$3)/12 -> 333.33333 | E34: =INDEX('Opex Plan'!$B$6:$D$6,1,E$3)/12 -> 333.33333 | F34: =INDEX('Opex Plan'!$B$6:$D$6,1,F$3)/12 -> 333.33333 | G34: =INDEX('Opex Plan'!$B$6:$D$6,1,G$3)/12 -> 333.33333 | H34: =INDEX('Opex Plan'!$B$6:$D$6,1,H$3)/12 -> 333.33333 | I34: =INDEX('Opex Plan'!$B$6:$D$6,1,I$3)/12 -> 333.33333 | ... AK34: =INDEX('Opex Plan'!$B$6:$D$6,1,AK$3)/12 -> 1166.6667
A35: Legal, accounting and trademark | B35: =INDEX('Opex Plan'!$B$7:$D$7,1,B$3)/12 -> 1250 | C35: =INDEX('Opex Plan'!$B$7:$D$7,1,C$3)/12 -> 1250 | D35: =INDEX('Opex Plan'!$B$7:$D$7,1,D$3)/12 -> 1250 | E35: =INDEX('Opex Plan'!$B$7:$D$7,1,E$3)/12 -> 1250 | F35: =INDEX('Opex Plan'!$B$7:$D$7,1,F$3)/12 -> 1250 | G35: =INDEX('Opex Plan'!$B$7:$D$7,1,G$3)/12 -> 1250 | H35: =INDEX('Opex Plan'!$B$7:$D$7,1,H$3)/12 -> 1250 | I35: =INDEX('Opex Plan'!$B$7:$D$7,1,I$3)/12 -> 1250 | ... AK35: =INDEX('Opex Plan'!$B$7:$D$7,1,AK$3)/12 -> 1666.6667
A36: Security audits (pen test, SOC 2) | B36: =INDEX('Opex Plan'!$B$8:$D$8,1,B$3)/12 -> 750 | C36: =INDEX('Opex Plan'!$B$8:$D$8,1,C$3)/12 -> 750 | D36: =INDEX('Opex Plan'!$B$8:$D$8,1,D$3)/12 -> 750 | E36: =INDEX('Opex Plan'!$B$8:$D$8,1,E$3)/12 -> 750 | F36: =INDEX('Opex Plan'!$B$8:$D$8,1,F$3)/12 -> 750 | G36: =INDEX('Opex Plan'!$B$8:$D$8,1,G$3)/12 -> 750 | H36: =INDEX('Opex Plan'!$B$8:$D$8,1,H$3)/12 -> 750 | I36: =INDEX('Opex Plan'!$B$8:$D$8,1,I$3)/12 -> 750 | ... AK36: =INDEX('Opex Plan'!$B$8:$D$8,1,AK$3)/12 -> 3750
A37: Marketing, events and CLE | B37: =INDEX('Opex Plan'!$B$9:$D$9,1,B$3)/12 -> 1250 | C37: =INDEX('Opex Plan'!$B$9:$D$9,1,C$3)/12 -> 1250 | D37: =INDEX('Opex Plan'!$B$9:$D$9,1,D$3)/12 -> 1250 | E37: =INDEX('Opex Plan'!$B$9:$D$9,1,E$3)/12 -> 1250 | F37: =INDEX('Opex Plan'!$B$9:$D$9,1,F$3)/12 -> 1250 | G37: =INDEX('Opex Plan'!$B$9:$D$9,1,G$3)/12 -> 1250 | H37: =INDEX('Opex Plan'!$B$9:$D$9,1,H$3)/12 -> 1250 | I37: =INDEX('Opex Plan'!$B$9:$D$9,1,I$3)/12 -> 1250 | ... AK37: =INDEX('Opex Plan'!$B$9:$D$9,1,AK$3)/12 -> 5833.3333
A38: Sales travel | B38: =INDEX('Opex Plan'!$B$10:$D$10,1,B$3)/12 -> 1000 | C38: =INDEX('Opex Plan'!$B$10:$D$10,1,C$3)/12 -> 1000 | D38: =INDEX('Opex Plan'!$B$10:$D$10,1,D$3)/12 -> 1000 | E38: =INDEX('Opex Plan'!$B$10:$D$10,1,E$3)/12 -> 1000 | F38: =INDEX('Opex Plan'!$B$10:$D$10,1,F$3)/12 -> 1000 | G38: =INDEX('Opex Plan'!$B$10:$D$10,1,G$3)/12 -> 1000 | H38: =INDEX('Opex Plan'!$B$10:$D$10,1,H$3)/12 -> 1000 | I38: =INDEX('Opex Plan'!$B$10:$D$10,1,I$3)/12 -> 1000 | ... AK38: =INDEX('Opex Plan'!$B$10:$D$10,1,AK$3)/12 -> 3000
A39: Contingency | B39: =SUM(B32:B38)*Assumptions!$B$28 -> 1261.6667 | C39: =SUM(C32:C38)*Assumptions!$B$28 -> 1261.6667 | D39: =SUM(D32:D38)*Assumptions!$B$28 -> 1261.6667 | E39: =SUM(E32:E38)*Assumptions!$B$28 -> 1261.6667 | F39: =SUM(F32:F38)*Assumptions!$B$28 -> 1261.6667 | G39: =SUM(G32:G38)*Assumptions!$B$28 -> 1261.6667 | H39: =SUM(H32:H38)*Assumptions!$B$28 -> 1261.6667 | I39: =SUM(I32:I38)*Assumptions!$B$28 -> 1261.6667 | ... AK39: =SUM(AK32:AK38)*Assumptions!$B$28 -> 8231.6667
A40: Total operating expenses | B40: =SUM(B32:B39) -> 13878.333 | C40: =SUM(C32:C39) -> 13878.333 | D40: =SUM(D32:D39) -> 13878.333 | E40: =SUM(E32:E39) -> 13878.333 | F40: =SUM(F32:F39) -> 13878.333 | G40: =SUM(G32:G39) -> 13878.333 | H40: =SUM(H32:H39) -> 13878.333 | I40: =SUM(I32:I39) -> 13878.333 | ... AK40: =SUM(AK32:AK39) -> 90548.333
A42: EBITDA (operating profit before tax) | B42: =B28-B40 -> -13878.333 | C42: =C28-C40 -> -13878.333 | D42: =D28-D40 -> -13878.333 | E42: =E28-E40 -> -12578.383 | F42: =F28-F40 -> -12322.308 | G42: =G28-G40 -> -12068.472 | H42: =H28-H40 -> -7450.454 | I42: =I28-I40 -> -6457.5922 | ... AK42: =AK28-AK40 -> 61343.905
A43: Capital purchases (demo & lab hardware) | B43: =SUMPRODUCT(('Opex Plan'!$C$19:$C$21=B$2)*'Opex Plan'!$B$19:$B$21) -> 5500 | C43: =SUMPRODUCT(('Opex Plan'!$C$19:$C$21=C$2)*'Opex Plan'!$B$19:$B$21) -> 0 | D43: =SUMPRODUCT(('Opex Plan'!$C$19:$C$21=D$2)*'Opex Plan'!$B$19:$B$21) -> 0 | E43: =SUMPRODUCT(('Opex Plan'!$C$19:$C$21=E$2)*'Opex Plan'!$B$19:$B$21) -> 0 | F43: =SUMPRODUCT(('Opex Plan'!$C$19:$C$21=F$2)*'Opex Plan'!$B$19:$B$21) -> 22500 | G43: =SUMPRODUCT(('Opex Plan'!$C$19:$C$21=G$2)*'Opex Plan'!$B$19:$B$21) -> 0 | H43: =SUMPRODUCT(('Opex Plan'!$C$19:$C$21=H$2)*'Opex Plan'!$B$19:$B$21) -> 0 | I43: =SUMPRODUCT(('Opex Plan'!$C$19:$C$21=I$2)*'Opex Plan'!$B$19:$B$21) -> 0 | ... AK43: =SUMPRODUCT(('Opex Plan'!$C$19:$C$21=AK$2)*'Opex Plan'!$B$19:$B$21) -> 0
A44: Net cash flow | B44: =B42-B43 -> -19378.333 | C44: =C42-C43 -> -13878.333 | D44: =D42-D43 -> -13878.333 | E44: =E42-E43 -> -12578.383 | F44: =F42-F43 -> -34822.308 | G44: =G42-G43 -> -12068.472 | H44: =H42-H43 -> -7450.454 | I44: =I42-I43 -> -6457.5922 | ... AK44: =AK42-AK43 -> 61343.905
A45: Cash balance (end of month) | B45: =Assumptions!$B$6+B44 -> -19378.333 | C45: =B45+C44 -> -33256.667 | D45: =C45+D44 -> -47135 | E45: =D45+E44 -> -59713.383 | F45: =E45+F44 -> -94535.692 | G45: =F45+G44 -> -106604.16 | H45: =G45+H44 -> -114054.62 | I45: =H45+I44 -> -120512.21 | J45: =I45+J44 -> -125985.62 | ... AK45: =AJ45+AK44 -> 65489.534
A47: ARR at list price (subscriptions x 12) | B47: =(B12*Assumptions!$B$12+B13*Assumptions!$C$12+B14*Assumptions!$D$12)*12 -> 0 | C47: =(C12*Assumptions!$B$12+C13*Assumptions!$C$12+C14*Assumptions!$D$12)*12 -> 0 | D47: =(D12*Assumptions!$B$12+D13*Assumptions!$C$12+D14*Assumptions!$D$12)*12 -> 0 | E47: =(E12*Assumptions!$B$12+E13*Assumptions!$C$12+E14*Assumptions!$D$12)*12 -> 6000 | F47: =(F12*Assumptions!$B$12+F13*Assumptions!$C$12+F14*Assumptions!$D$12)*12 -> 11947.55 | G47: =(G12*Assumptions!$B$12+G13*Assumptions!$C$12+G14*Assumptions!$D$12)*12 -> 17843.109 | H47: =(H12*Assumptions!$B$12+H13*Assumptions!$C$12+H14*Assumptions!$D$12)*12 -> 39687.132 | I47: =(I12*Assumptions!$B$12+I13*Assumptions!$C$12+I14*Assumptions!$D$12)*12 -> 61340.203 | ... AK47: =(AK12*Assumptions!$B$12+AK13*Assumptions!$C$12+AK14*Assumptions!$D$12)*12 -> 1780192.9
...

Sheet Hardware BOM
A1: Hardware Bill of Materials (cost to you, USD)
A2: Sept 2026 prices. Memory shortages roughly doubled GPU and server prices in 12-18 months, so re-quote before every proposal (quotes valid 7-14 days). Blue cells are inputs.
A4: Practice tier: GB10 desktop (NVIDIA DGX Spark or ASUS Ascent GX10), 128 GB unified memory
A5: Component | B5: Qty | C5: Unit cost ($) | D5: Extended ($) | E5: Source / notes
A6: NVIDIA DGX Spark (GB10, 128 GB, 4 TB) | B6: 1 | C6: 4699 | D6: =B6*C6 -> 4699 | E6: $4,699 after Feb 2026 increase (was $3,999). ASUS Ascent GX10 1 TB is $3,999. https://aicybr.com/blog/gb10-ai-workstations-dgx-spark-dell-asus-hp-lenovo
A7: UPS, ~1 kVA line-interactive | B7: 1 | C7: 400 | D7: =B7*C7 -> 400 | E7: Estimate ($250-600 range)
A8: Encrypted backup drive (config and search indexes) | B8: 1 | C8: 250 | D8: =B8*C8 -> 250 | E8: Estimate; NAND prices elevated in 2026
A9: Cabling, labels, tamper-evident seals | B9: 1 | C9: 150 | D9: =B9*C9 -> 150 | E9: Estimate
A10: Total hardware cost - Practice | D10: =SUM(D6:D9) -> 5499
A11: Serves ~10-40 staff: ~4-8 simultaneous short requests; 1-3 long-document jobs at once (estimate from published benchmarks).
A13: Firm tier: Workstation with 1x NVIDIA RTX PRO 6000 Blackwell (96 GB), 128 GB RAM
A14: Component | B14: Qty | C14: Unit cost ($) | D14: Extended ($) | E14: Source / notes
A15: Dell Pro Max T2 workstation, Core Ultra 9, 128 GB, 1x RTX PRO 6000 | B15: 1 | C15: 19628 | D15: =B15*C15 -> 19628 | E15: $19,627.94 (MSRP $25,516) Sept 2026, out of stock at that seller. https://www.monitors.com/products/dell-pro-max-tower-t2-core-ultra-9-285-128gb-rtx-pro-6000-blackwell
A16: Additional 4 TB NVMe for models and indexes | B16: 1 | C16: 650 | D16: =B16*C16 -> 650 | E16: Estimate; NAND prices elevated in 2026
A17: UPS, ~2.2 kVA | B17: 1 | C17: 1100 | D17: =B17*C17 -> 1100 | E17: Estimate ($700-1,500 range)
A18: Backup storage (small NAS or encrypted drives) | B18: 1 | C18: 700 | D18: =B18*C18 -> 700 | E18: Estimate
A19: Networking and accessories | B19: 1 | C19: 250 | D19: =B19*C19 -> 250 | E19: Estimate
A20: Total hardware cost - Firm | D20: =SUM(D15:D19) -> 22328
A21: Serves ~50-150 staff: ~50 simultaneous short requests at ~31 tokens/s each (measured, vLLM); 6-10 long-document jobs at once.
A23: Enterprise tier: Tower with 2x NVIDIA RTX PRO 6000 Blackwell Max-Q (192 GB GPU memory), Threadripper PRO, 256 GB ECC
A24: Component | B24: Qty | C24: Unit cost ($) | D24: Extended ($) | E24: Source / notes
A25: NVIDIA RTX PRO 6000 Blackwell Max-Q 96 GB | B25: 2 | C25: 17000 | D25: =B25*C25 -> 34000 | E25: $16,000 NVIDIA list; Newegg $17,999.99 (Sept 2026). https://www.thundercompute.com/blog/nvidia-rtx-pro-6000-pricing
A26: Workstation platform: Threadripper PRO, 256 GB ECC, 8 TB NVMe, 1600 W PSU (builder quote) | B26: 1 | C26: 20000 | D26: =B26*C26 -> 20000 | E26: Estimate: $50-60k all-in for the 2-GPU tier minus GPUs. Builders: Puget, Bizon, Exxact.
A27: UPS, ~3 kVA | B27: 1 | C27: 1800 | D27: =B27*C27 -> 1800 | E27: Estimate ($1,000-2,000 range)
A28: Backup NAS | B28: 1 | C28: 1500 | D28: =B28*C28 -> 1500 | E28: Estimate
A29: 10 GbE networking and accessories | B29: 1 | C29: 700 | D29: =B29*C29 -> 700 | E29: Estimate
A30: Total hardware cost - Enterprise | D30: =SUM(D25:D29) -> 58000
A31: Serves ~100-300 staff: ~100 simultaneous short requests; 15-20 long-document jobs at once (estimate). Beyond 300 users, quote a 4x RTX PRO 6000 server (~$126k).

Sheet Benchmarks
A1: Market price benchmarks (for positioning, not formulas)
A2: From the competitor research (02-competition.md). (3P) = third-party estimate; the vendor doesn't publish the price.
A4: Vendor / product | B4: Category | C4: Published or reported price | D4: Deployment | E4: Source
A5: Harvey | B5: Legal AI (cloud) | C5: ~$1,000-2,000/seat/month mid-market (3P) | D5: Cloud only | E5: https://www.insidelegalai.com/articles/harvey-ai-2026-pricing-midsized
A6: Thomson Reuters CoCounsel Legal | B6: Legal AI (cloud) | C6: ~$492/user/month for a 5-attorney firm (3P) | D6: Cloud only | E6: https://costbench.com/software/ai-legal-tools/cocounsel/
A7: Lexis+ AI / Protege | B7: Legal AI (cloud) | C7: ~$250-500/seat/month small firms (3P) | D7: Cloud only | E7: https://www.vaquill.ai/blog/lexis-plus-ai-pricing
A8: Clio Work (vLex Vincent) | B8: Legal AI (cloud) | C8: $199/user/month | D8: Cloud only | E8: https://www.lawnext.com/2026/04/clio-work-clios-ai-workspace-is-now-available-to-solo-and-smaller-law-firms-as-a-standalone-product.html
A9: InPractice / Chartely / Medrecords AI | B9: Medical record review (cloud) | C9: $0.04-0.10 per page | D9: Cloud only | E9: https://medrecords.ai/guides/medical-record-review-cost/
A10: Legal nurse consultant | B10: Medical record review (human) | C10: ~$2,500-5,000 per case (3P) | D10: People | E10: https://medrecords.ai/guides/medical-record-review-cost/
A11: Freed | B11: Ambient scribe (cloud) | C11: $39-119/clinician/month | D11: Cloud with BAA | E11: https://www.getfreed.ai/pricing
A12: Microsoft Dragon Copilot | B12: Ambient scribe (cloud) | C12: $159.99/user/month reseller list (Practice SKU, retired 2026) | D12: Azure cloud | E12: https://www.schneider.im/microsoft-dragon-copilot-price-decrease-licensing-changes/
A13: Jump | B13: RIA meeting AI (cloud) | C13: $100/advisor/month (~$80 annual) | D13: Cloud only | E13: https://jump.ai/pricing
A14: Blue J | B14: Tax research AI (cloud) | C14: $1,498/user/year | D14: Cloud only | E14: https://www.bluej.com/pricing
A15: Iternal AirgapAI | B15: Local AI app (laptop) | C15: $35/month or $697 perpetual per user | D15: On-device | E15: https://iternal.ai/airgapai
... A22: Microsoft 365 Copilot | B22: Horizontal AI (cloud) | C22: ~$30/user/month (2023 launch list price; 2026 SMB pricing unverified) | D22: Cloud with BAA | E22: Microsoft launch announcement, Nov 2023 (not re-verified for 2026)
